Workbook

Sheet Site Information
A1: PAN-INDIA SITE CONSUMPTION TEMPLATE | Perpetual / Continuous | v3.0
A2: Fill Site Information ONCE. Enter daily readings continuously — all months, all years. Upload same file after each entry.
A4: SITE DETAILS (Fill once — do not change)
A5: Site Code | B5: LKO1 | C5: e.g. LKO1, DEL5, MUM1 | D5: MANDATORY
A6: Site Name | B6: ASSPL LKO1 | C6: Full name of the site | D6: MANDATORY
A7: Region | B7: North | C7: North / South / East / West / Central | D7: MANDATORY
A8: Business Unit | B8: FC | C8: FC / SC / AMZL / AMXL / GSF | D8: MANDATORY
A9: Capacity (GSF) | B9: 1194597 | C9: Gross Square Feet — used for EUI calc | D9: MANDATORY
A10: Contact Person | B10: Vinod Minhas | C10: RME / FM in-charge name | D10: MANDATORY
A11: Email | B11: vmminhas@amazon.com | C11: Contact email address | D11: MANDATORY
A12: Phone | B12: 8988385268 | C12: 10-digit mobile number | D12: MANDATORY
A13: Data Start Date | B13: 46023 | C13: Date from which data entry begins (DD/MM/YYYY) | D13: MANDATORY
A15: FILE NAMING: SITECODE_Consumption.xlsx | Example: LKO1_Consumption.xlsx (ONE FILE PER SITE — PERPETUAL)
A16: UPLOAD: WorkDocs > Region > Site Code > SITECODE_Consumption.xlsx | Upload same file after each daily entry
A18: COLOR GUIDE: YELLOW = Enter data here (manual input by technician) GREEN = Auto-calculated — DO NOT EDIT GRAY = Auto-linked from previous row — DO NOT EDIT BLUE = Date column (DD/MM/YYYY)
A24: MONTHLY EUI TARGETS (kWh/GSF/Day) — Update every year
A25: Month | B25: EUI Target | C25: Hint | D25: Status
A26: January | B26: 0.26 | C26: EUI target for January (kWh/GSF/Day) | D26: MANDATORY
A27: February | B27: 0.32 | C27: EUI target for February (kWh/GSF/Day) | D27: MANDATORY
A28: March | B28: 0.46 | C28: EUI target for March (kWh/GSF/Day) | D28: MANDATORY
A29: April | B29: 0.67 | C29: EUI target for April (kWh/GSF/Day) | D29: MANDATORY
A30: May | B30: 0.72 | C30: EUI target for May (kWh/GSF/Day) | D30: MANDATORY
A31: June | B31: 0.76 | C31: EUI target for June (kWh/GSF/Day) | D31: MANDATORY
A32: July | B32: 0.8 | C32: EUI target for July (kWh/GSF/Day) | D32: MANDATORY
A33: August | B33: 0.84 | C33: EUI target for August (kWh/GSF/Day) | D33: MANDATORY
A34: September | B34: 0.74 | C34: EUI target for September (kWh/GSF/Day) | D34: MANDATORY
A35: October | B35: 0.68 | C35: EUI target for October (kWh/GSF/Day) | D35: MANDATORY
A36: November | B36: 0.52 | C36: EUI target for November (kWh/GSF/Day) | D36: MANDATORY
A37: December | B37: 0.48 | C37: EUI target for December (kWh/GSF/Day) | D37: MANDATORY
A38: Monthly EUI Targets: Enter site-specific monthly targets above. These are auto-referenced in Energy Master sheet.

Sheet Energy - Master
A1: ENERGY & CONSUMPTION MASTER SHEET | 100% Auto-populated | GREEN = Auto-fetched | Only DATE is manual
A2: Date (DD/MM/YYYY) | B2: EB Consumption (HT kWh) | C2: DG Consumption (kWh) | D2: Solar Consumption (kWh) | E2: Total Power Consumption (kWh) | F2: Total HSD Consumption (Ltr) | G2: EB MTD (kWh) | H2: DG MTD (kWh) | I2: Solar MTD (kWh) | J2: Total Power MTD (kWh) | K2: Budget Unit | L2: Budget MTD | M2: EUI / Day (Target ) | N2: EUI/Day (Actual) | O2: EUI MTD | P2: Raw Water Consumption (KL) | Q2: STP Inlet (KL) | R2: STP Outlet (KL) | S2: Total Water Consumption (KL) | T2: Comments / Remarks
A3: 46023 | B3: =IFERROR(IF('LT Panel Feeder Readings'!E4="","",'LT Panel Feeder Readings'!E4),"") -> 7137 | C3: =IFERROR(IF('LT Panel Feeder Readings'!W4="","",IF('LT Panel Feeder Readings'!W4="",0,'LT Panel Feeder Readings'!W4)+IF('LT Panel Feeder Readings'!Z4="",0,'LT Panel Feeder Readings'!Z4)),"") -> 0 | D3: =IFERROR(IF('LT Panel Feeder Readings'!BG4="","",IF('LT Panel Feeder Readings'!BG4="",0,'LT Panel Feeder Readings'!BG4)+IF('LT Panel Feeder Readings'!BJ4="",0,'LT Panel Feeder Readings'!BJ4)),"") -> 2063 | E3: =IF(B3="","",B3+IF(C3="",0,C3)+IF(D3="",0,D3)) -> 9200 | F3: =IFERROR(IF('Fuel Status'!E5="","",IF('Fuel Status'!E5="",0,'Fuel Status'!E5)+IF('Fuel Status'!J5="",0,'Fuel Status'!J5)+IF('Fuel Status'!O5="",0,'Fuel Status'!O5)),"") -> 65 | G3: =IF(B3="","",B3) -> 7137 | H3: =IF(C3="","",C3) -> 0 | I3: =IF(D3="","",D3) -> 2063 | J3: =IF(E3="","",E3) -> 9200 | K3: =(M3*'Site Information'!$B$9)/DAY(EOMONTH(A$3,0)) -> 10019.201 | L3: =IF(K3="","",K3) -> 10019.201 | M3: {=IF(A3="","",INDEX('Site Information'!$B$26:$B$37,MONTH(A3)))} -> 0.26 | N3: =E3*M3/K3 -> 0.2387416 | O3: =J3*M3/L3 -> 0.2387416 | P3: =IFERROR(IF('Raw Water'!U4="","",'Raw Water'!U4),"") -> 35 | Q3: =IFERROR(IF(STP!U4="","",STP!U4),"") -> 48 | R3: =IFERROR(IF(STP!V4="","",STP!V4),"") -> 42 | S3: =IF(P3="","",P3) -> 35
A4: 46024 | B4: =IFERROR(IF('LT Panel Feeder Readings'!E5="","",'LT Panel Feeder Readings'!E5),"") -> 9255 | C4: =IFERROR(IF('LT Panel Feeder Readings'!W5="","",IF('LT Panel Feeder Readings'!W5="",0,'LT Panel Feeder Readings'!W5)+IF('LT Panel Feeder Readings'!Z5="",0,'LT Panel Feeder Readings'!Z5)),"") -> 91 | D4: =IFERROR(IF('LT Panel Feeder Readings'!BG5="","",IF('LT Panel Feeder Readings'!BG5="",0,'LT Panel Feeder Readings'!BG5)+IF('LT Panel Feeder Readings'!BJ5="",0,'LT Panel Feeder Readings'!BJ5)),"") -> 645 | E4: =IF(B4="","",B4+IF(C4="",0,C4)+IF(D4="",0,D4)) -> 9991 | F4: =IFERROR(IF('Fuel Status'!E6="","",IF('Fuel Status'!E6="",0,'Fuel Status'!E6)+IF('Fuel Status'!J6="",0,'Fuel Status'!J6)+IF('Fuel Status'!O6="",0,'Fuel Status'!O6)),"") -> 0 | G4: =IF(B4="","",IF(MONTH(A4)<>MONTH(A3),B4,G3+B4)) -> 16392 | H4: =IF(C4="","",IF(MONTH(A4)<>MONTH(A3),C4,H3+C4)) -> 91 | I4: =IF(D4="","",IF(MONTH(A4)<>MONTH(A3),D4,I3+D4)) -> 2708 | J4: =IF(E4="","",IF(MONTH(A4)<>MONTH(A3),E4,J3+E4)) -> 19191 | K4: =(M4*'Site Information'!$B$9)/DAY(EOMONTH(A$3,0)) -> 10019.201 | L4: =IF(K4="","",IF(MONTH(A4)<>MONTH(A3),K4,L3+K4)) -> 20038.401 | M4: {=IF(A4="","",INDEX('Site Information'!$B$26:$B$37,MONTH(A4)))} -> 0.26 | N4: =E4*M4/K4 -> 0.25926819 | O4: =J4*M4/L4 -> 0.24900489 | P4: =IFERROR(IF('Raw Water'!U5="","",'Raw Water'!U5),"") -> 20 | Q4: =IFERROR(IF(STP!U5="","",STP!U5),"") -> 50 | R4: =IFERROR(IF(STP!V5="","",STP!V5),"") -> 42 | S4: =IF(P4="","",P4) -> 20
A5: 46025 | B5: =IFERROR(IF('LT Panel Feeder Readings'!E6="","",'LT Panel Feeder Readings'!E6),"") -> 8924 | C5: =IFERROR(IF('LT Panel Feeder Readings'!W6="","",IF('LT Panel Feeder Readings'!W6="",0,'LT Panel Feeder Readings'!W6)+IF('LT Panel Feeder Readings'!Z6="",0,'LT Panel Feeder Readings'!Z6)),"") -> 0 | D5: =IFERROR(IF('LT Panel Feeder Readings'!BG6="","",IF('LT Panel Feeder Readings'!BG6="",0,'LT Panel Feeder Readings'!BG6)+IF('LT Panel Feeder Readings'!BJ6="",0,'LT Panel Feeder Readings'!BJ6)),"") -> 992 | E5: =IF(B5="","",B5+IF(C5="",0,C5)+IF(D5="",0,D5)) -> 9916 | F5: =IFERROR(IF('Fuel Status'!E7="","",IF('Fuel Status'!E7="",0,'Fuel Status'!E7)+IF('Fuel Status'!J7="",0,'Fuel Status'!J7)+IF('Fuel Status'!O7="",0,'Fuel Status'!O7)),"") -> 0 | G5: =IF(B5="","",IF(MONTH(A5)<>MONTH(A4),B5,G4+B5)) -> 25316 | H5: =IF(C5="","",IF(MONTH(A5)<>MONTH(A4),C5,H4+C5)) -> 91 | I5: =IF(D5="","",IF(MONTH(A5)<>MONTH(A4),D5,I4+D5)) -> 3700 | J5: =IF(E5="","",IF(MONTH(A5)<>MONTH(A4),E5,J4+E5)) -> 29107 | K5: =(M5*'Site Information'!$B$9)/DAY(EOMONTH(A$3,0)) -> 10019.201 | L5: =IF(K5="","",IF(MONTH(A5)<>MONTH(A4),K5,L4+K5)) -> 30057.602 | M5: {=IF(A5="","",INDEX('Site Information'!$B$26:$B$37,MONTH(A5)))} -> 0.26 | N5: =E5*M5/K5 -> 0.25732193 | O5: =J5*M5/L5 -> 0.25177724 | P5: =IFERROR(IF('Raw Water'!U6="","",'Raw Water'!U6),"") -> 22 | Q5: =IFERROR(IF(STP!U6="","",STP!U6),"") -> 49 | R5: =IFERROR(IF(STP!V6="","",STP!V6),"") -> 43 | S5: =IF(P5="","",P5) -> 22
A6: 46026 | B6: =IFERROR(IF('LT Panel Feeder Readings'!E7="","",'LT Panel Feeder Readings'!E7),"") -> 7671 | C6: =IFERROR(IF('LT Panel Feeder Readings'!W7="","",IF('LT Panel Feeder Readings'!W7="",0,'LT Panel Feeder Readings'!W7)+IF('LT Panel Feeder Readings'!Z7="",0,'LT Panel Feeder Readings'!Z7)),"") -> 0 | D6: =IFERROR(IF('LT Panel Feeder Readings'!BG7="","",IF('LT Panel Feeder Readings'!BG7="",0,'LT Panel Feeder Readings'!BG7)+IF('LT Panel Feeder Readings'!BJ7="",0,'LT Panel Feeder Readings'!BJ7)),"") -> 1854 | E6: =IF(B6="","",B6+IF(C6="",0,C6)+IF(D6="",0,D6)) -> 9525 | F6: =IFERROR(IF('Fuel Status'!E8="","",IF('Fuel Status'!E8="",0,'Fuel Status'!E8)+IF('Fuel Status'!J8="",0,'Fuel Status'!J8)+IF('Fuel Status'!O8="",0,'Fuel Status'!O8)),"") -> 30 | G6: =IF(B6="","",IF(MONTH(A6)<>MONTH(A5),B6,G5+B6)) -> 32987 | H6: =IF(C6="","",IF(MONTH(A6)<>MONTH(A5),C6,H5+C6)) -> 91 | I6: =IF(D6="","",IF(MONTH(A6)<>MONTH(A5),D6,I5+D6)) -> 5554 | J6: =IF(E6="","",IF(MONTH(A6)<>MONTH(A5),E6,J5+E6)) -> 38632 | K6: =(M6*'Site Information'!$B$9)/DAY(EOMONTH(A$3,0)) -> 10019.201 | L6: =IF(K6="","",IF(MONTH(A6)<>MONTH(A5),K6,L5+K6)) -> 40076.803 | M6: {=IF(A6="","",INDEX('Site Information'!$B$26:$B$37,MONTH(A6)))} -> 0.26 | N6: =E6*M6/K6 -> 0.24717541 | O6: =J6*M6/L6 -> 0.25062678 | P6: =IFERROR(IF('Raw Water'!U7="","",'Raw Water'!U7),"") -> 23 | Q6: =IFERROR(IF(STP!U7="","",STP!U7),"") -> 47 | R6: =IFERROR(IF(STP!V7="","",STP!V7),"") -> 41 | S6: =IF(P6="","",P6) -> 23
A7: 46027 | B7: =IFERROR(IF('LT Panel Feeder Readings'!E8="","",'LT Panel Feeder Readings'!E8),"") -> 7089 | C7: =IFERROR(IF('LT Panel Feeder Readings'!W8="","",IF('LT Panel Feeder Readings'!W8="",0,'LT Panel Feeder Readings'!W8)+IF('LT Panel Feeder Readings'!Z8="",0,'LT Panel Feeder Readings'!Z8)),"") -> 450 | D7: =IFERROR(IF('LT Panel Feeder Readings'!BG8="","",IF('LT Panel Feeder Readings'!BG8="",0,'LT Panel Feeder Readings'!BG8)+IF('LT Panel Feeder Readings'!BJ8="",0,'LT Panel Feeder Readings'!BJ8)),"") -> 2106 | E7: =IF(B7="","",B7+IF(C7="",0,C7)+IF(D7="",0,D7)) -> 9645 | F7: =IFERROR(IF('Fuel Status'!E9="","",IF('Fuel Status'!E9="",0,'Fuel Status'!E9)+IF('Fuel Status'!J9="",0,'Fuel Status'!J9)+IF('Fuel Status'!O9="",0,'Fuel Status'!O9)),"") -> 190 | G7: =IF(B7="","",IF(MONTH(A7)<>MONTH(A6),B7,G6+B7)) -> 40076 | H7: =IF(C7="","",IF(MONTH(A7)<>MONTH(A6),C7,H6+C7)) -> 541 | I7: =IF(D7="","",IF(MONTH(A7)<>MONTH(A6),D7,I6+D7)) -> 7660 | J7: =IF(E7="","",IF(MONTH(A7)<>MONTH(A6),E7,J6+E7)) -> 48277 | K7: =(M7*'Site Information'!$B$9)/DAY(EOMONTH(A$3,0)) -> 10019.201 | L7: =IF(K7="","",IF(MONTH(A7)<>MONTH(A6),K7,L6+K7)) -> 50096.003 | M7: {=IF(A7="","",INDEX('Site Information'!$B$26:$B$37,MONTH(A7)))} -> 0.26 | N7: =E7*M7/K7 -> 0.25028943 | O7: =J7*M7/L7 -> 0.25055931 | P7: =IFERROR(IF('Raw Water'!U8="","",'Raw Water'!U8),"") -> 36 | Q7: =IFERROR(IF(STP!U8="","",STP!U8),"") -> 40 | R7: =IFERROR(IF(STP!V8="","",STP!V8),"") -> 35 | S7: =IF(P7="","",P7) -> 36
A8: 46028 | B8: =IFERROR(IF('LT Panel Feeder Readings'!E9="","",'LT Panel Feeder Readings'!E9),"") -> 7997 | C8: =IFERROR(IF('LT Panel Feeder Readings'!W9="","",IF('LT Panel Feeder Readings'!W9="",0,'LT Panel Feeder Readings'!W9)+IF('LT Panel Feeder Readings'!Z9="",0,'LT Panel Feeder Readings'!Z9)),"") -> 191 | D8: =IFERROR(IF('LT Panel Feeder Readings'!BG9="","",IF('LT Panel Feeder Readings'!BG9="",0,'LT Panel Feeder Readings'!BG9)+IF('LT Panel Feeder Readings'!BJ9="",0,'LT Panel Feeder Readings'!BJ9)),"") -> 1372 | E8: =IF(B8="","",B8+IF(C8="",0,C8)+IF(D8="",0,D8)) -> 9560 | F8: =IFERROR(IF('Fuel Status'!E10="","",IF('Fuel Status'!E10="",0,'Fuel Status'!E10)+IF('Fuel Status'!J10="",0,'Fuel Status'!J10)+IF('Fuel Status'!O10="",0,'Fuel Status'!O10)),"") -> 0 | G8: =IF(B8="","",IF(MONTH(A8)<>MONTH(A7),B8,G7+B8)) -> 48073 | H8: =IF(C8="","",IF(MONTH(A8)<>MONTH(A7),C8,H7+C8)) -> 732 | I8: =IF(D8="","",IF(MONTH(A8)<>MONTH(A7),D8,I7+D8)) -> 9032 | J8: =IF(E8="","",IF(MONTH(A8)<>MONTH(A7),E8,J7+E8)) -> 57837 | K8: =(M8*'Site Information'!$B$9)/DAY(EOMONTH(A$3,0)) -> 10019.201 | L8: =IF(K8="","",IF(MONTH(A8)<>MONTH(A7),K8,L7+K8)) -> 60115.204 | M8: {=IF(A8="","",INDEX('Site Information'!$B$26:$B$37,MONTH(A8)))} -> 0.26 | N8: =E8*M8/K8 -> 0.24808366 | O8: =J8*M8/L8 -> 0.2501467 | P8: =IFERROR(IF('Raw Water'!U9="","",'Raw Water'!U9),"") -> 45 | Q8: =IFERROR(IF(STP!U9="","",STP!U9),"") -> 48 | R8: =IFERROR(IF(STP!V9="","",STP!V9),"") -> 43 | S8: =IF(P8="","",P8) -> 45
A9: 46029 | B9: =IFERROR(IF('LT Panel Feeder Readings'!E10="","",'LT Panel Feeder Readings'!E10),"") -> 8212 | C9: =IFERROR(IF('LT Panel Feeder Readings'!W10="","",IF('LT Panel Feeder Readings'!W10="",0,'LT Panel Feeder Readings'!W10)+IF('LT Panel Feeder Readings'!Z10="",0,'LT Panel Feeder Readings'!Z10)),"") -> 0 | D9: =IFERROR(IF('LT Panel Feeder Readings'!BG10="","",IF('LT Panel Feeder Readings'!BG10="",0,'LT Panel Feeder Readings'!BG10)+IF('LT Panel Feeder Readings'!BJ10="",0,'LT Panel Feeder Readings'!BJ10)),"") -> 1540 | E9: =IF(B9="","",B9+IF(C9="",0,C9)+IF(D9="",0,D9)) -> 9752 | F9: =IFERROR(IF('Fuel Status'!E11="","",IF('Fuel Status'!E11="",0,'Fuel Status'!E11)+IF('Fuel Status'!J11="",0,'Fuel Status'!J11)+IF('Fuel Status'!O11="",0,'Fuel Status'!O11)),"") -> 180 | G9: =IF(B9="","",IF(MONTH(A9)<>MONTH(A8),B9,G8+B9)) -> 56285 | H9: =IF(C9="","",IF(MONTH(A9)<>MONTH(A8),C9,H8+C9)) -> 732 | I9: =IF(D9="","",IF(MONTH(A9)<>MONTH(A8),D9,I8+D9)) -> 10572 | J9: =IF(E9="","",IF(MONTH(A9)<>MONTH(A8),E9,J8+E9)) -> 67589 | K9: =(M9*'Site Information'!$B$9)/DAY(EOMONTH(A$3,0)) -> 10019.201 | L9: =IF(K9="","",IF(MONTH(A9)<>MONTH(A8),K9,L8+K9)) -> 70134.405 | M9: {=IF(A9="","",INDEX('Site Information'!$B$26:$B$37,MONTH(A9)))} -> 0.26 | N9: =E9*M9/K9 -> 0.2530661 | O9: =J9*M9/L9 -> 0.25056376 | P9: =IFERROR(IF('Raw Water'!U10="","",'Raw Water'!U10),"") -> 27 | Q9: =IFERROR(IF(STP!U10="","",STP!U10),"") -> 55 | R9: =IFERROR(IF(STP!V10="","",STP!V10),"") -> 50 | S9: =IF(P9="","",P9) -> 27
A10: 46030 | B10: =IFERROR(IF('LT Panel Feeder Readings'!E11="","",'LT Panel Feeder Readings'!E11),"") -> 7624 | C10: =IFERROR(IF('LT Panel Feeder Readings'!W11="","",IF('LT Panel Feeder Readings'!W11="",0,'LT Panel Feeder Readings'!W11)+IF('LT Panel Feeder Readings'!Z11="",0,'LT Panel Feeder Readings'!Z11)),"") -> 228 | D10: =IFERROR(IF('LT Panel Feeder Readings'!BG11="","",IF('LT Panel Feeder Readings'!BG11="",0,'LT Panel Feeder Readings'!BG11)+IF('LT Panel Feeder Readings'!BJ11="",0,'LT Panel Feeder Readings'!BJ11)),"") -> 1712 | E10: =IF(B10="","",B10+IF(C10="",0,C10)+IF(D10="",0,D10)) -> 9564 | F10: =IFERROR(IF('Fuel Status'!E12="","",IF('Fuel Status'!E12="",0,'Fuel Status'!E12)+IF('Fuel Status'!J12="",0,'Fuel Status'!J12)+IF('Fuel Status'!O12="",0,'Fuel Status'!O12)),"") -> 60 | G10: =IF(B10="","",IF(MONTH(A10)<>MONTH(A9),B10,G9+B10)) -> 63909 | H10: =IF(C10="","",IF(MONTH(A10)<>MONTH(A9),C10,H9+C10)) -> 960 | I10: =IF(D10="","",IF(MONTH(A10)<>MONTH(A9),D10,I9+D10)) -> 12284 | J10: =IF(E10="","",IF(MONTH(A10)<>MONTH(A9),E10,J9+E10)) -> 77153 | K10: =(M10*'Site Information'!$B$9)/DAY(EOMONTH(A$3,0)) -> 10019.201 | L10: =IF(K10="","",IF(MONTH(A10)<>MONTH(A9),K10,L9+K10)) -> 80153.605 | M10: {=IF(A10="","",INDEX('Site Information'!$B$26:$B$37,MONTH(A10)))} -> 0.26 | N10: =E10*M10/K10 -> 0.24818746 | O10: =J10*M10/L10 -> 0.25026672 | P10: =IFERROR(IF('Raw Water'!U11="","",'Raw Water'!U11),"") -> 29 | Q10: =IFERROR(IF(STP!U11="","",STP!U11),"") -> 50 | R10: =IFERROR(IF(STP!V11="","",STP!V11),"") -> 45 | S10: =IF(P10="","",P10) -> 29
A11: 46031 | B11: =IFERROR(IF('LT Panel Feeder Readings'!E12="","",'LT Panel Feeder Readings'!E12),"") -> 7496 | C11: =IFERROR(IF('LT Panel Feeder Readings'!W12="","",IF('LT Panel Feeder Readings'!W12="",0,'LT Panel Feeder Readings'!W12)+IF('LT Panel Feeder Readings'!Z12="",0,'LT Panel Feeder Readings'!Z12)),"") -> 151 | D11: =IFERROR(IF('LT Panel Feeder Readings'!BG12="","",IF('LT Panel Feeder Readings'!BG12="",0,'LT Panel Feeder Readings'!BG12)+IF('LT Panel Feeder Readings'!BJ12="",0,'LT Panel Feeder Readings'!BJ12)),"") -> 1835 | E11: =IF(B11="","",B11+IF(C11="",0,C11)+IF(D11="",0,D11)) -> 9482 | F11: =IFERROR(IF('Fuel Status'!E13="","",IF('Fuel Status'!E13="",0,'Fuel Status'!E13)+IF('Fuel Status'!J13="",0,'Fuel Status'!J13)+IF('Fuel Status'!O13="",0,'Fuel Status'!O13)),"") -> 0 | G11: =IF(B11="","",IF(MONTH(A11)<>MONTH(A10),B11,G10+B11)) -> 71405 | H11: =IF(C11="","",IF(MONTH(A11)<>MONTH(A10),C11,H10+C11)) -> 1111 | I11: =IF(D11="","",IF(MONTH(A11)<>MONTH(A10),D11,I10+D11)) -> 14119 | J11: =IF(E11="","",IF(MONTH(A11)<>MONTH(A10),E11,J10+E11)) -> 86635 | K11: =(M11*'Site Information'!$B$9)/DAY(EOMONTH(A$3,0)) -> 10019.201 | L11: =IF(K11="","",IF(MONTH(A11)<>MONTH(A10),K11,L10+K11)) -> 90172.806 | M11: {=IF(A11="","",INDEX('Site Information'!$B$26:$B$37,MONTH(A11)))} -> 0.26 | N11: =E11*M11/K11 -> 0.24605955 | O11: =J11*M11/L11 -> 0.24979926 | P11: =IFERROR(IF('Raw Water'!U12="","",'Raw Water'!U12),"") -> 67 | Q11: =IFERROR(IF(STP!U12="","",STP!U12),"") -> 48 | R11: =IFERROR(IF(STP!V12="","",STP!V12),"") -> 42 | S11: =IF(P11="","",P11) -> 67
A12: 46032 | B12: =IFERROR(IF('LT Panel Feeder Readings'!E13="","",'LT Panel Feeder Readings'!E13),"") -> 7013 | C12: =IFERROR(IF('LT Panel Feeder Readings'!W13="","",IF('LT Panel Feeder Readings'!W13="",0,'LT Panel Feeder Readings'!W13)+IF('LT Panel Feeder Readings'!Z13="",0,'LT Panel Feeder Readings'!Z13)),"") -> 0 | D12: =IFERROR(IF('LT Panel Feeder Readings'!BG13="","",IF('LT Panel Feeder Readings'!BG13="",0,'LT Panel Feeder Readings'!BG13)+IF('LT Panel Feeder Readings'!BJ13="",0,'LT Panel Feeder Readings'!BJ13)),"") -> 2300 | E12: =IF(B12="","",B12+IF(C12="",0,C12)+IF(D12="",0,D12)) -> 9313 | F12: =IFERROR(IF('Fuel Status'!E14="","",IF('Fuel Status'!E14="",0,'Fuel Status'!E14)+IF('Fuel Status'!J14="",0,'Fuel Status'!J14)+IF('Fuel Status'!O14="",0,'Fuel Status'!O14)),"") -> 0 | G12: =IF(B12="","",IF(MONTH(A12)<>MONTH(A11),B12,G11+B12)) -> 78418 | H12: =IF(C12="","",IF(MONTH(A12)<>MONTH(A11),C12,H11+C12)) -> 1111 | I12: =IF(D12="","",IF(MONTH(A12)<>MONTH(A11),D12,I11+D12)) -> 16419 | J12: =IF(E12="","",IF(MONTH(A12)<>MONTH(A11),E12,J11+E12)) -> 95948 | K12: =(M12*'Site Information'!$B$9)/DAY(EOMONTH(A$3,0)) -> 10019.201 | L12: =IF(K12="","",IF(MONTH(A12)<>MONTH(A11),K12,L11+K12)) -> 100192.01 | M12: {=IF(A12="","",INDEX('Site Information'!$B$26:$B$37,MONTH(A12)))} -> 0.26 | N12: =E12*M12/K12 -> 0.24167397 | O12: =J12*M12/L12 -> 0.24898673 | P12: =IFERROR(IF('Raw Water'!U13="","",'Raw Water'!U13),"") -> 44 | Q12: =IFERROR(IF(STP!U13="","",STP!U13),"") -> 50 | R12: =IFERROR(IF(STP!V13="","",STP!V13),"") -> 44 | S12: =IF(P12="","",P12) -> 44
A13: 46033 | B13: =IFERROR(IF('LT Panel Feeder Readings'!E14="","",'LT Panel Feeder Readings'!E14),"") -> 6849 | C13: =IFERROR(IF('LT Panel Feeder Readings'!W14="","",IF('LT Panel Feeder Readings'!W14="",0,'LT Panel Feeder Readings'!W14)+IF('LT Panel Feeder Readings'!Z14="",0,'LT Panel Feeder Readings'!Z14)),"") -> 0 | D13: =IFERROR(IF('LT Panel Feeder Readings'!BG14="","",IF('LT Panel Feeder Readings'!BG14="",0,'LT Panel Feeder Readings'!BG14)+IF('LT Panel Feeder Readings'!BJ14="",0,'LT Panel Feeder Readings'!BJ14)),"") -> 2226 | E13: =IF(B13="","",B13+IF(C13="",0,C13)+IF(D13="",0,D13)) -> 9075 | F13: =IFERROR(IF('Fuel Status'!E15="","",IF('Fuel Status'!E15="",0,'Fuel Status'!E15)+IF('Fuel Status'!J15="",0,'Fuel Status'!J15)+IF('Fuel Status'!O15="",0,'Fuel Status'!O15)),"") -> 55 | G13: =IF(B13="","",IF(MONTH(A13)<>MONTH(A12),B13,G12+B13)) -> 85267 | H13: =IF(C13="","",IF(MONTH(A13)<>MONTH(A12),C13,H12+C13)) -> 1111 | I13: =IF(D13="","",IF(MONTH(A13)<>MONTH(A12),D13,I12+D13)) -> 18645 | J13: =IF(E13="","",IF(MONTH(A13)<>MONTH(A12),E13,J12+E13)) -> 105023 | K13: =(M13*'Site Information'!$B$9)/DAY(EOMONTH(A$3,0)) -> 10019.201 | L13: =IF(K13="","",IF(MONTH(A13)<>MONTH(A12),K13,L12+K13)) -> 110211.21 | M13: {=IF(A13="","",INDEX('Site Information'!$B$26:$B$37,MONTH(A13)))} -> 0.26 | N13: =E13*M13/K13 -> 0.23549783 | O13: =J13*M13/L13 -> 0.24776047 | P13: =IFERROR(IF('Raw Water'!U14="","",'Raw Water'!U14),"") -> 35 | Q13: =IFERROR(IF(STP!U14="","",STP!U14),"") -> 52 | R13: =IFERROR(IF(STP!V14="","",STP!V14),"") -> 46 | S13: =IF(P13="","",P13) -> 35
A14: 46034 | B14: =IFERROR(IF('LT Panel Feeder Readings'!E15="","",'LT Panel Feeder Readings'!E15),"") -> 6884 | C14: =IFERROR(IF('LT Panel Feeder Readings'!W15="","",IF('LT Panel Feeder Readings'!W15="",0,'LT Panel Feeder Readings'!W15)+IF('LT Panel Feeder Readings'!Z15="",0,'LT Panel Feeder Readings'!Z15)),"") -> 112 | D14: =IFERROR(IF('LT Panel Feeder Readings'!BG15="","",IF('LT Panel Feeder Readings'!BG15="",0,'LT Panel Feeder Readings'!BG15)+IF('LT Panel Feeder Readings'!BJ15="",0,'LT Panel Feeder Readings'!BJ15)),"") -> 2222 | E14: =IF(B14="","",B14+IF(C14="",0,C14)+IF(D14="",0,D14)) -> 9218 | F14: =IFERROR(IF('Fuel Status'!E16="","",IF('Fuel Status'!E16="",0,'Fuel Status'!E16)+IF('Fuel Status'!J16="",0,'Fuel Status'!J16)+IF('Fuel Status'!O16="",0,'Fuel Status'!O16)),"") -> 0 | G14: =IF(B14="","",IF(MONTH(A14)<>MONTH(A13),B14,G13+B14)) -> 92151 | H14: =IF(C14="","",IF(MONTH(A14)<>MONTH(A13),C14,H13+C14)) -> 1223 | I14: =IF(D14="","",IF(MONTH(A14)<>MONTH(A13),D14,I13+D14)) -> 20867 | J14: =IF(E14="","",IF(MONTH(A14)<>MONTH(A13),E14,J13+E14)) -> 114241 | K14: =(M14*'Site Information'!$B$9)/DAY(EOMONTH(A$3,0)) -> 10019.201 | L14: =IF(K14="","",IF(MONTH(A14)<>MONTH(A13),K14,L13+K14)) -> 120230.41 | M14: {=IF(A14="","",INDEX('Site Information'!$B$26:$B$37,MONTH(A14)))} -> 0.26 | N14: =E14*M14/K14 -> 0.2392087 | O14: =J14*M14/L14 -> 0.24704782 | P14: =IFERROR(IF('Raw Water'!U15="","",'Raw Water'!U15),"") -> 28 | Q14: =IFERROR(IF(STP!U15="","",STP!U15),"") -> 46 | R14: =IFERROR(IF(STP!V15="","",STP!V15),"") -> 39 | S14: =IF(P14="","",P14) -> 28
A15: 46035 | B15: =IFERROR(IF('LT Panel Feeder Readings'!E16="","",'LT Panel Feeder Readings'!E16),"") -> 6781 | C15: =IFERROR(IF('LT Panel Feeder Readings'!W16="","",IF('LT Panel Feeder Readings'!W16="",0,'LT Panel Feeder Readings'!W16)+IF('LT Panel Feeder Readings'!Z16="",0,'LT Panel Feeder Readings'!Z16)),"") -> 0 | D15: =IFERROR(IF('LT Panel Feeder Readings'!BG16="","",IF('LT Panel Feeder Readings'!BG16="",0,'LT Panel Feeder Readings'!BG16)+IF('LT Panel Feeder Readings'!BJ16="",0,'LT Panel Feeder Readings'!BJ16)),"") -> 2375 | E15: =IF(B15="","",B15+IF(C15="",0,C15)+IF(D15="",0,D15)) -> 9156 | F15: =IFERROR(IF('Fuel Status'!E17="","",IF('Fuel Status'!E17="",0,'Fuel Status'!E17)+IF('Fuel Status'!J17="",0,'Fuel Status'!J17)+IF('Fuel Status'!O17="",0,'Fuel Status'!O17)),"") -> 0 | G15: =IF(B15="","",IF(MONTH(A15)<>MONTH(A14),B15,G14+B15)) -> 98932 | H15: =IF(C15="","",IF(MONTH(A15)<>MONTH(A14),C15,H14+C15)) -> 1223 | I15: =IF(D15="","",IF(MONTH(A15)<>MONTH(A14),D15,I14+D15)) -> 23242 | J15: =IF(E15="","",IF(MONTH(A15)<>MONTH(A14),E15,J14+E15)) -> 123397 | K15: =(M15*'Site Information'!$B$9)/DAY(EOMONTH(A$3,0)) -> 10019.201 | L15: =IF(K15="","",IF(MONTH(A15)<>MONTH(A14),K15,L14+K15)) -> 130249.61 | M15: {=IF(A15="","",INDEX('Site Information'!$B$26:$B$37,MONTH(A15)))} -> 0.26 | N15: =E15*M15/K15 -> 0.23759979 | O15: =J15*M15/L15 -> 0.24632105 | P15: =IFERROR(IF('Raw Water'!U16="","",'Raw Water'!U16),"") -> 31 | Q15: =IFERROR(IF(STP!U16="","",STP!U16),"") -> 48 | R15: =IFERROR(IF(STP!V16="","",STP!V16),"") -> 42 | S15: =IF(P15="","",P15) -> 31
... A367: 46387 | B367: =IFERROR(IF('LT Panel Feeder Readings'!E368="","",'LT Panel Feeder Readings'!E368),"") | C367: =IFERROR(IF('LT Panel Feeder Readings'!W368="","",IF('LT Panel Feeder Readings'!W368="",0,'LT Panel Feeder Readings'!W368)+IF('LT Panel Feeder Readings'!Z368="",0,'LT Panel Feeder Readings'!Z368)),"") | D367: =IFERROR(IF('LT Panel Feeder Readings'!BG368="","",IF('LT Panel Feeder Readings'!BG368="",0,'LT Panel Feeder Readings'!BG368)+IF('LT Panel Feeder Readings'!BJ368="",0,'LT Panel Feeder Readings'!BJ368)),"") | E367: =IF(B367="","",B367+IF(C367="",0,C367)+IF(D367="",0,D367)) | F367: =IFERROR(IF('Fuel Status'!E369="","",IF('Fuel Status'!E369="",0,'Fuel Status'!E369)+IF('Fuel Status'!J369="",0,'Fuel Status'!J369)+IF('Fuel Status'!O369="",0,'Fuel Status'!O369)),"") -> 0 | G367: =IF(B367="","",IF(MONTH(A367)<>MONTH(A366),B367,G366+B367)) | H367: =IF(C367="","",IF(MONTH(A367)<>MONTH(A366),C367,H366+C367)) | I367: =IF(D367="","",IF(MONTH(A367)<>MONTH(A366),D367,I366+D367)) | J367: =IF(E367="","",IF(MONTH(A367)<>MONTH(A366),E367,J366+E367)) | K367: =(M367*'Site Information'!$B$9)/DAY(EOMONTH(A$3,0)) -> 18496.986 | L367: =IF(K367="","",IF(MONTH(A367)<>MONTH(A366),K367,L366+K367)) -> 573406.56 | M367: {=IF(A367="","",INDEX('Site Information'!$B$26:$B$37,MONTH(A367)))} -> 0.48 | N367: =E367*M367/K367 -> #VALUE! | O367: =J367*M367/L367 -> #VALUE! | P367: =IFERROR(IF('Raw Water'!U368="","",'Raw Water'!U368),"") | Q367: =IFERROR(IF(STP!U368="","",STP!U368),"") | R367: =IFERROR(IF(STP!V368="","",STP!V368),"") | S367: =IF(P367="","",P367)
A368: 46388 | B368: =IFERROR(IF('LT Panel Feeder Readings'!E369="","",'LT Panel Feeder Readings'!E369),"") | C368: =IFERROR(IF('LT Panel Feeder Readings'!W369="","",IF('LT Panel Feeder Readings'!W369="",0,'LT Panel Feeder Readings'!W369)+IF('LT Panel Feeder Readings'!Z369="",0,'LT Panel Feeder Readings'!Z369)),"") | D368: =IFERROR(IF('LT Panel Feeder Readings'!BG369="","",IF('LT Panel Feeder Readings'!BG369="",0,'LT Panel Feeder Readings'!BG369)+IF('LT Panel Feeder Readings'!BJ369="",0,'LT Panel Feeder Readings'!BJ369)),"") | E368: =IF(B368="","",B368+IF(C368="",0,C368)+IF(D368="",0,D368)) | F368: =IFERROR(IF('Fuel Status'!E370="","",IF('Fuel Status'!E370="",0,'Fuel Status'!E370)+IF('Fuel Status'!J370="",0,'Fuel Status'!J370)+IF('Fuel Status'!O370="",0,'Fuel Status'!O370)),"") -> 0 | G368: =IF(B368="","",IF(MONTH(A368)<>MONTH(A367),B368,G367+B368)) | H368: =IF(C368="","",IF(MONTH(A368)<>MONTH(A367),C368,H367+C368)) | I368: =IF(D368="","",IF(MONTH(A368)<>MONTH(A367),D368,I367+D368)) | J368: =IF(E368="","",IF(MONTH(A368)<>MONTH(A367),E368,J367+E368)) | N368: =E368*M368/K368 -> #VALUE! | O368: =J368*M368/L368 -> #VALUE! | P368: =IFERROR(IF('Raw Water'!U369="","",'Raw Water'!U369),"") | Q368: =IFERROR(IF(STP!U369="","",STP!U369),"") | R368: =IFERROR(IF(STP!V369="","",STP!V369),"") | S368: =IF(P368="","",P368)
A369: 46389 | B369: =IFERROR(IF('LT Panel Feeder Readings'!E370="","",'LT Panel Feeder Readings'!E370),"") | C369: =IFERROR(IF('LT Panel Feeder Readings'!W370="","",IF('LT Panel Feeder Readings'!W370="",0,'LT Panel Feeder Readings'!W370)+IF('LT Panel Feeder Readings'!Z370="",0,'LT Panel Feeder Readings'!Z370)),"") | D369: =IFERROR(IF('LT Panel Feeder Readings'!BG370="","",IF('LT Panel Feeder Readings'!BG370="",0,'LT Panel Feeder Readings'!BG370)+IF('LT Panel Feeder Readings'!BJ370="",0,'LT Panel Feeder Readings'!BJ370)),"") | E369: =IF(B369="","",B369+IF(C369="",0,C369)+IF(D369="",0,D369)) | F369: =IFERROR(IF('Fuel Status'!E371="","",IF('Fuel Status'!E371="",0,'Fuel Status'!E371)+IF('Fuel Status'!J371="",0,'Fuel Status'!J371)+IF('Fuel Status'!O371="",0,'Fuel Status'!O371)),"") -> 0 | G369: =IF(B369="","",IF(MONTH(A369)<>MONTH(A368),B369,G368+B369)) | H369: =IF(C369="","",IF(MONTH(A369)<>MONTH(A368),C369,H368+C369)) | I369: =IF(D369="","",IF(MONTH(A369)<>MONTH(A368),D369,I368+D369)) | J369: =IF(E369="","",IF(MONTH(A369)<>MONTH(A368),E369,J368+E369)) | N369: =E369*M369/K369 -> #VALUE! | O369: =J369*M369/L369 -> #VALUE! | P369: =IFERROR(IF('Raw Water'!U370="","",'Raw Water'!U370),"") | Q369: =IFERROR(IF(STP!U370="","",STP!U370),"") | R369: =IFERROR(IF(STP!V370="","",STP!V370),"") | S369: =IF(P369="","",P369)
A370: 46390 | B370: =IFERROR(IF('LT Panel Feeder Readings'!E371="","",'LT Panel Feeder Readings'!E371),"") | C370: =IFERROR(IF('LT Panel Feeder Readings'!W371="","",IF('LT Panel Feeder Readings'!W371="",0,'LT Panel Feeder Readings'!W371)+IF('LT Panel Feeder Readings'!Z371="",0,'LT Panel Feeder Readings'!Z371)),"") | D370: =IFERROR(IF('LT Panel Feeder Readings'!BG371="","",IF('LT Panel Feeder Readings'!BG371="",0,'LT Panel Feeder Readings'!BG371)+IF('LT Panel Feeder Readings'!BJ371="",0,'LT Panel Feeder Readings'!BJ371)),"") | E370: =IF(B370="","",B370+IF(C370="",0,C370)+IF(D370="",0,D370)) | F370: =IFERROR(IF('Fuel Status'!E372="","",IF('Fuel Status'!E372="",0,'Fuel Status'!E372)+IF('Fuel Status'!J372="",0,'Fuel Status'!J372)+IF('Fuel Status'!O372="",0,'Fuel Status'!O372)),"") -> 0 | G370: =IF(B370="","",IF(MONTH(A370)<>MONTH(A369),B370,G369+B370)) | H370: =IF(C370="","",IF(MONTH(A370)<>MONTH(A369),C370,H369+C370)) | I370: =IF(D370="","",IF(MONTH(A370)<>MONTH(A369),D370,I369+D370)) | J370: =IF(E370="","",IF(MONTH(A370)<>MONTH(A369),E370,J369+E370)) | N370: =E370*M370/K370 -> #VALUE! | O370: =J370*M370/L370 -> #VALUE! | P370: =IFERROR(IF('Raw Water'!U371="","",'Raw Water'!U371),"") | Q370: =IFERROR(IF(STP!U371="","",STP!U371),"") | R370: =IFERROR(IF(STP!V371="","",STP!V371),"") | S370: =IF(P370="","",P370)
A371: 46391 | B371: =IFERROR(IF('LT Panel Feeder Readings'!E372="","",'LT Panel Feeder Readings'!E372),"") | C371: =IFERROR(IF('LT Panel Feeder Readings'!W372="","",IF('LT Panel Feeder Readings'!W372="",0,'LT Panel Feeder Readings'!W372)+IF('LT Panel Feeder Readings'!Z372="",0,'LT Panel Feeder Readings'!Z372)),"") | D371: =IFERROR(IF('LT Panel Feeder Readings'!BG372="","",IF('LT Panel Feeder Readings'!BG372="",0,'LT Panel Feeder Readings'!BG372)+IF('LT Panel Feeder Readings'!BJ372="",0,'LT Panel Feeder Readings'!BJ372)),"") | E371: =IF(B371="","",B371+IF(C371="",0,C371)+IF(D371="",0,D371)) | F371: =IFERROR(IF('Fuel Status'!E373="","",IF('Fuel Status'!E373="",0,'Fuel Status'!E373)+IF('Fuel Status'!J373="",0,'Fuel Status'!J373)+IF('Fuel Status'!O373="",0,'Fuel Status'!O373)),"") -> 0 | G371: =IF(B371="","",IF(MONTH(A371)<>MONTH(A370),B371,G370+B371)) | H371: =IF(C371="","",IF(MONTH(A371)<>MONTH(A370),C371,H370+C371)) | I371: =IF(D371="","",IF(MONTH(A371)<>MONTH(A370),D371,I370+D371)) | J371: =IF(E371="","",IF(MONTH(A371)<>MONTH(A370),E371,J370+E371)) | N371: =E371*M371/K371 -> #VALUE! | O371: =J371*M371/L371 -> #VALUE! | P371: =IFERROR(IF('Raw Water'!U372="","",'Raw Water'!U372),"") | Q371: =IFERROR(IF(STP!U372="","",STP!U372),"") | R371: =IFERROR(IF(STP!V372="","",STP!V372),"") | S371: =IF(P371="","",P371)
A372: 46392 | B372: =IFERROR(IF('LT Panel Feeder Readings'!E373="","",'LT Panel Feeder Readings'!E373),"") | C372: =IFERROR(IF('LT Panel Feeder Readings'!W373="","",IF('LT Panel Feeder Readings'!W373="",0,'LT Panel Feeder Readings'!W373)+IF('LT Panel Feeder Readings'!Z373="",0,'LT Panel Feeder Readings'!Z373)),"") | D372: =IFERROR(IF('LT Panel Feeder Readings'!BG373="","",IF('LT Panel Feeder Readings'!BG373="",0,'LT Panel Feeder Readings'!BG373)+IF('LT Panel Feeder Readings'!BJ373="",0,'LT Panel Feeder Readings'!BJ373)),"") | E372: =IF(B372="","",B372+IF(C372="",0,C372)+IF(D372="",0,D372)) | F372: =IFERROR(IF('Fuel Status'!E374="","",IF('Fuel Status'!E374="",0,'Fuel Status'!E374)+IF('Fuel Status'!J374="",0,'Fuel Status'!J374)+IF('Fuel Status'!O374="",0,'Fuel Status'!O374)),"") -> 0 | G372: =IF(B372="","",IF(MONTH(A372)<>MONTH(A371),B372,G371+B372)) | H372: =IF(C372="","",IF(MONTH(A372)<>MONTH(A371),C372,H371+C372)) | I372: =IF(D372="","",IF(MONTH(A372)<>MONTH(A371),D372,I371+D372)) | J372: =IF(E372="","",IF(MONTH(A372)<>MONTH(A371),E372,J371+E372)) | N372: =E372*M372/K372 -> #VALUE! | O372: =J372*M372/L372 -> #VALUE! | P372: =IFERROR(IF('Raw Water'!U373="","",'Raw Water'!U373),"") | Q372: =IFERROR(IF(STP!U373="","",STP!U373),"") | R372: =IFERROR(IF(STP!V373="","",STP!V373),"") | S372: =IF(P372="","",P372)
A373: 46393 | B373: =IFERROR(IF('LT Panel Feeder Readings'!E374="","",'LT Panel Feeder Readings'!E374),"") | C373: =IFERROR(IF('LT Panel Feeder Readings'!W374="","",IF('LT Panel Feeder Readings'!W374="",0,'LT Panel Feeder Readings'!W374)+IF('LT Panel Feeder Readings'!Z374="",0,'LT Panel Feeder Readings'!Z374)),"") | D373: =IFERROR(IF('LT Panel Feeder Readings'!BG374="","",IF('LT Panel Feeder Readings'!BG374="",0,'LT Panel Feeder Readings'!BG374)+IF('LT Panel Feeder Readings'!BJ374="",0,'LT Panel Feeder Readings'!BJ374)),"") | E373: =IF(B373="","",B373+IF(C373="",0,C373)+IF(D373="",0,D373)) | F373: =IFERROR(IF('Fuel Status'!E375="","",IF('Fuel Status'!E375="",0,'Fuel Status'!E375)+IF('Fuel Status'!J375="",0,'Fuel Status'!J375)+IF('Fuel Status'!O375="",0,'Fuel Status'!O375)),"") -> 0 | G373: =IF(B373="","",IF(MONTH(A373)<>MONTH(A372),B373,G372+B373)) | H373: =IF(C373="","",IF(MONTH(A373)<>MONTH(A372),C373,H372+C373)) | I373: =IF(D373="","",IF(MONTH(A373)<>MONTH(A372),D373,I372+D373)) | J373: =IF(E373="","",IF(MONTH(A373)<>MONTH(A372),E373,J372+E373)) | N373: =E373*M373/K373 -> #VALUE! | O373: =J373*M373/L373 -> #VALUE! | P373: =IFERROR(IF('Raw Water'!U374="","",'Raw Water'!U374),"") | Q373: =IFERROR(IF(STP!U374="","",STP!U374),"") | R373: =IFERROR(IF(STP!V374="","",STP!V374),"") | S373: =IF(P373="","",P373)
A374: 46394 | B374: =IFERROR(IF('LT Panel Feeder Readings'!E375="","",'LT Panel Feeder Readings'!E375),"") | C374: =IFERROR(IF('LT Panel Feeder Readings'!W375="","",IF('LT Panel Feeder Readings'!W375="",0,'LT Panel Feeder Readings'!W375)+IF('LT Panel Feeder Readings'!Z375="",0,'LT Panel Feeder Readings'!Z375)),"") | D374: =IFERROR(IF('LT Panel Feeder Readings'!BG375="","",IF('LT Panel Feeder Readings'!BG375="",0,'LT Panel Feeder Readings'!BG375)+IF('LT Panel Feeder Readings'!BJ375="",0,'LT Panel Feeder Readings'!BJ375)),"") | E374: =IF(B374="","",B374+IF(C374="",0,C374)+IF(D374="",0,D374)) | F374: =IFERROR(IF('Fuel Status'!E376="","",IF('Fuel Status'!E376="",0,'Fuel Status'!E376)+IF('Fuel Status'!J376="",0,'Fuel Status'!J376)+IF('Fuel Status'!O376="",0,'Fuel Status'!O376)),"") -> 0 | G374: =IF(B374="","",IF(MONTH(A374)<>MONTH(A373),B374,G373+B374)) | H374: =IF(C374="","",IF(MONTH(A374)<>MONTH(A373),C374,H373+C374)) | I374: =IF(D374="","",IF(MONTH(A374)<>MONTH(A373),D374,I373+D374)) | J374: =IF(E374="","",IF(MONTH(A374)<>MONTH(A373),E374,J373+E374)) | N374: =E374*M374/K374 -> #VALUE! | O374: =J374*M374/L374 -> #VALUE! | P374: =IFERROR(IF('Raw Water'!U375="","",'Raw Water'!U375),"") | Q374: =IFERROR(IF(STP!U375="","",STP!U375),"") | R374: =IFERROR(IF(STP!V375="","",STP!V375),"") | S374: =IF(P374="","",P374)
A375: 46395 | B375: =IFERROR(IF('LT Panel Feeder Readings'!E376="","",'LT Panel Feeder Readings'!E376),"") | C375: =IFERROR(IF('LT Panel Feeder Readings'!W376="","",IF('LT Panel Feeder Readings'!W376="",0,'LT Panel Feeder Readings'!W376)+IF('LT Panel Feeder Readings'!Z376="",0,'LT Panel Feeder Readings'!Z376)),"") | D375: =IFERROR(IF('LT Panel Feeder Readings'!BG376="","",IF('LT Panel Feeder Readings'!BG376="",0,'LT Panel Feeder Readings'!BG376)+IF('LT Panel Feeder Readings'!BJ376="",0,'LT Panel Feeder Readings'!BJ376)),"") | E375: =IF(B375="","",B375+IF(C375="",0,C375)+IF(D375="",0,D375)) | F375: =IFERROR(IF('Fuel Status'!E377="","",IF('Fuel Status'!E377="",0,'Fuel Status'!E377)+IF('Fuel Status'!J377="",0,'Fuel Status'!J377)+IF('Fuel Status'!O377="",0,'Fuel Status'!O377)),"") -> 0 | G375: =IF(B375="","",IF(MONTH(A375)<>MONTH(A374),B375,G374+B375)) | H375: =IF(C375="","",IF(MONTH(A375)<>MONTH(A374),C375,H374+C375)) | I375: =IF(D375="","",IF(MONTH(A375)<>MONTH(A374),D375,I374+D375)) | J375: =IF(E375="","",IF(MONTH(A375)<>MONTH(A374),E375,J374+E375)) | N375: =E375*M375/K375 -> #VALUE! | O375: =J375*M375/L375 -> #VALUE! | P375: =IFERROR(IF('Raw Water'!U376="","",'Raw Water'!U376),"") | Q375: =IFERROR(IF(STP!U376="","",STP!U376),"") | R375: =IFERROR(IF(STP!V376="","",STP!V376),"") | S375: =IF(P375="","",P375)
A376: 46396 | B376: =IFERROR(IF('LT Panel Feeder Readings'!E377="","",'LT Panel Feeder Readings'!E377),"") | C376: =IFERROR(IF('LT Panel Feeder Readings'!W377="","",IF('LT Panel Feeder Readings'!W377="",0,'LT Panel Feeder Readings'!W377)+IF('LT Panel Feeder Readings'!Z377="",0,'LT Panel Feeder Readings'!Z377)),"") | D376: =IFERROR(IF('LT Panel Feeder Readings'!BG377="","",IF('LT Panel Feeder Readings'!BG377="",0,'LT Panel Feeder Readings'!BG377)+IF('LT Panel Feeder Readings'!BJ377="",0,'LT Panel Feeder Readings'!BJ377)),"") | E376: =IF(B376="","",B376+IF(C376="",0,C376)+IF(D376="",0,D376)) | F376: =IFERROR(IF('Fuel Status'!E378="","",IF('Fuel Status'!E378="",0,'Fuel Status'!E378)+IF('Fuel Status'!J378="",0,'Fuel Status'!J378)+IF('Fuel Status'!O378="",0,'Fuel Status'!O378)),"") -> 0 | G376: =IF(B376="","",IF(MONTH(A376)<>MONTH(A375),B376,G375+B376)) | H376: =IF(C376="","",IF(MONTH(A376)<>MONTH(A375),C376,H375+C376)) | I376: =IF(D376="","",IF(MONTH(A376)<>MONTH(A375),D376,I375+D376)) | J376: =IF(E376="","",IF(MONTH(A376)<>MONTH(A375),E376,J375+E376)) | N376: =E376*M376/K376 -> #VALUE! | O376: =J376*M376/L376 -> #VALUE! | P376: =IFERROR(IF('Raw Water'!U377="","",'Raw Water'!U377),"") | Q376: =IFERROR(IF(STP!U377="","",STP!U377),"") | R376: =IFERROR(IF(STP!V377="","",STP!V377),"") | S376: =IF(P376="","",P376)
A377: 46397 | B377: =IFERROR(IF('LT Panel Feeder Readings'!E378="","",'LT Panel Feeder Readings'!E378),"") | C377: =IFERROR(IF('LT Panel Feeder Readings'!W378="","",IF('LT Panel Feeder Readings'!W378="",0,'LT Panel Feeder Readings'!W378)+IF('LT Panel Feeder Readings'!Z378="",0,'LT Panel Feeder Readings'!Z378)),"") | D377: =IFERROR(IF('LT Panel Feeder Readings'!BG378="","",IF('LT Panel Feeder Readings'!BG378="",0,'LT Panel Feeder Readings'!BG378)+IF('LT Panel Feeder Readings'!BJ378="",0,'LT Panel Feeder Readings'!BJ378)),"") | E377: =IF(B377="","",B377+IF(C377="",0,C377)+IF(D377="",0,D377)) | F377: =IFERROR(IF('Fuel Status'!E379="","",IF('Fuel Status'!E379="",0,'Fuel Status'!E379)+IF('Fuel Status'!J379="",0,'Fuel Status'!J379)+IF('Fuel Status'!O379="",0,'Fuel Status'!O379)),"") -> 0 | G377: =IF(B377="","",IF(MONTH(A377)<>MONTH(A376),B377,G376+B377)) | H377: =IF(C377="","",IF(MONTH(A377)<>MONTH(A376),C377,H376+C377)) | I377: =IF(D377="","",IF(MONTH(A377)<>MONTH(A376),D377,I376+D377)) | J377: =IF(E377="","",IF(MONTH(A377)<>MONTH(A376),E377,J376+E377)) | N377: =E377*M377/K377 -> #VALUE! | O377: =J377*M377/L377 -> #VALUE! | P377: =IFERROR(IF('Raw Water'!U378="","",'Raw Water'!U378),"") | Q377: =IFERROR(IF(STP!U378="","",STP!U378),"") | R377: =IFERROR(IF(STP!V378="","",STP!V378),"") | S377: =IF(P377="","",P377)
A378: 46398 | B378: =IFERROR(IF('LT Panel Feeder Readings'!E379="","",'LT Panel Feeder Readings'!E379),"") | C378: =IFERROR(IF('LT Panel Feeder Readings'!W379="","",IF('LT Panel Feeder Readings'!W379="",0,'LT Panel Feeder Readings'!W379)+IF('LT Panel Feeder Readings'!Z379="",0,'LT Panel Feeder Readings'!Z379)),"") | D378: =IFERROR(IF('LT Panel Feeder Readings'!BG379="","",IF('LT Panel Feeder Readings'!BG379="",0,'LT Panel Feeder Readings'!BG379)+IF('LT Panel Feeder Readings'!BJ379="",0,'LT Panel Feeder Readings'!BJ379)),"") | E378: =IF(B378="","",B378+IF(C378="",0,C378)+IF(D378="",0,D378)) | F378: =IFERROR(IF('Fuel Status'!E380="","",IF('Fuel Status'!E380="",0,'Fuel Status'!E380)+IF('Fuel Status'!J380="",0,'Fuel Status'!J380)+IF('Fuel Status'!O380="",0,'Fuel Status'!O380)),"") -> 0 | G378: =IF(B378="","",IF(MONTH(A378)<>MONTH(A377),B378,G377+B378)) | H378: =IF(C378="","",IF(MONTH(A378)<>MONTH(A377),C378,H377+C378)) | I378: =IF(D378="","",IF(MONTH(A378)<>MONTH(A377),D378,I377+D378)) | J378: =IF(E378="","",IF(MONTH(A378)<>MONTH(A377),E378,J377+E378)) | N378: =E378*M378/K378 -> #VALUE! | O378: =J378*M378/L378 -> #VALUE! | P378: =IFERROR(IF('Raw Water'!U379="","",'Raw Water'!U379),"") | Q378: =IFERROR(IF(STP!U379="","",STP!U379),"") | R378: =IFERROR(IF(STP!V379="","",STP!V379),"") | S378: =IF(P378="","",P378)
A379: 46399 | B379: =IFERROR(IF('LT Panel Feeder Readings'!E380="","",'LT Panel Feeder Readings'!E380),"") | C379: =IFERROR(IF('LT Panel Feeder Readings'!W380="","",IF('LT Panel Feeder Readings'!W380="",0,'LT Panel Feeder Readings'!W380)+IF('LT Panel Feeder Readings'!Z380="",0,'LT Panel Feeder Readings'!Z380)),"") | D379: =IFERROR(IF('LT Panel Feeder Readings'!BG380="","",IF('LT Panel Feeder Readings'!BG380="",0,'LT Panel Feeder Readings'!BG380)+IF('LT Panel Feeder Readings'!BJ380="",0,'LT Panel Feeder Readings'!BJ380)),"") | E379: =IF(B379="","",B379+IF(C379="",0,C379)+IF(D379="",0,D379)) | F379: =IFERROR(IF('Fuel Status'!E381="","",IF('Fuel Status'!E381="",0,'Fuel Status'!E381)+IF('Fuel Status'!J381="",0,'Fuel Status'!J381)+IF('Fuel Status'!O381="",0,'Fuel Status'!O381)),"") -> 0 | G379: =IF(B379="","",IF(MONTH(A379)<>MONTH(A378),B379,G378+B379)) | H379: =IF(C379="","",IF(MONTH(A379)<>MONTH(A378),C379,H378+C379)) | I379: =IF(D379="","",IF(MONTH(A379)<>MONTH(A378),D379,I378+D379)) | J379: =IF(E379="","",IF(MONTH(A379)<>MONTH(A378),E379,J378+E379)) | N379: =E379*M379/K379 -> #VALUE! | O379: =J379*M379/L379 -> #VALUE! | P379: =IFERROR(IF('Raw Water'!U380="","",'Raw Water'!U380),"") | Q379: =IFERROR(IF(STP!U380="","",STP!U380),"") | R379: =IFERROR(IF(STP!V380="","",STP!V380),"") | S379: =IF(P379="","",P379)
... A602: 46622 | B602: =IFERROR(IF('LT Panel Feeder Readings'!E603="","",'LT Panel Feeder Readings'!E603),"") | C602: =IFERROR(IF('LT Panel Feeder Readings'!W603="","",IF('LT Panel Feeder Readings'!W603="",0,'LT Panel Feeder Readings'!W603)+IF('LT Panel Feeder Readings'!Z603="",0,'LT Panel Feeder Readings'!Z603)),"") | D602: =IFERROR(IF('LT Panel Feeder Readings'!BG603="","",IF('LT Panel Feeder Readings'!BG603="",0,'LT Panel Feeder Readings'!BG603)+IF('LT Panel Feeder Readings'!BJ603="",0,'LT Panel Feeder Readings'!BJ603)),"") | E602: =IF(B602="","",B602+IF(C602="",0,C602)+IF(D602="",0,D602)) | F602: =IFERROR(IF('Fuel Status'!E604="","",IF('Fuel Status'!E604="",0,'Fuel Status'!E604)+IF('Fuel Status'!J604="",0,'Fuel Status'!J604)+IF('Fuel Status'!O604="",0,'Fuel Status'!O604)),"") -> 0 | G602: =IF(B602="","",IF(MONTH(A602)<>MONTH(A601),B602,G601+B602)) | H602: =IF(C602="","",IF(MONTH(A602)<>MONTH(A601),C602,H601+C602)) | I602: =IF(D602="","",IF(MONTH(A602)<>MONTH(A601),D602,I601+D602)) | J602: =IF(E602="","",IF(MONTH(A602)<>MONTH(A601),E602,J601+E602)) | N602: =E602*M602/K602 -> #VALUE! | O602: =J602*M602/L602 -> #VALUE! | P602: =IFERROR(IF('Raw Water'!U603="","",'Raw Water'!U603),"") | Q602: =IFERROR(IF(STP!U603="","",STP!U603),"") | R602: =IFERROR(IF(STP!V603="","",STP!V603),"") | S602: =IF(P602="","",P602)
A603: 46623 | B603: =IFERROR(IF('LT Panel Feeder Readings'!E604="","",'LT Panel Feeder Readings'!E604),"") | C603: =IFERROR(IF('LT Panel Feeder Readings'!W604="","",IF('LT Panel Feeder Readings'!W604="",0,'LT Panel Feeder Readings'!W604)+IF('LT Panel Feeder Readings'!Z604="",0,'LT Panel Feeder Readings'!Z604)),"") | D603: =IFERROR(IF('LT Panel Feeder Readings'!BG604="","",IF('LT Panel Feeder Readings'!BG604="",0,'LT Panel Feeder Readings'!BG604)+IF('LT Panel Feeder Readings'!BJ604="",0,'LT Panel Feeder Readings'!BJ604)),"") | E603: =IF(B603="","",B603+IF(C603="",0,C603)+IF(D603="",0,D603)) | F603: =IFERROR(IF('Fuel Status'!E605="","",IF('Fuel Status'!E605="",0,'Fuel Status'!E605)+IF('Fuel Status'!J605="",0,'Fuel Status'!J605)+IF('Fuel Status'!O605="",0,'Fuel Status'!O605)),"") -> 0 | G603: =IF(B603="","",IF(MONTH(A603)<>MONTH(A602),B603,G602+B603)) | H603: =IF(C603="","",IF(MONTH(A603)<>MONTH(A602),C603,H602+C603)) | I603: =IF(D603="","",IF(MONTH(A603)<>MONTH(A602),D603,I602+D603)) | J603: =IF(E603="","",IF(MONTH(A603)<>MONTH(A602),E603,J602+E603)) | N603: =E603*M603/K603 -> #VALUE! | O603: =IF(OR(J603="",L603="",L603=0),"",ROUND(J603/L603,4)) | P603: =IFERROR(IF('Raw Water'!U604="","",'Raw Water'!U604),"") | Q603: =IFERROR(IF(STP!U604="","",STP!U604),"") | R603: =IFERROR(IF(STP!V604="","",STP!V604),"") | S603: =IF(P603="","",P603)
A604: 46624 | B604: =IFERROR(IF('LT Panel Feeder Readings'!E605="","",'LT Panel Feeder Readings'!E605),"") | C604: =IFERROR(IF('LT Panel Feeder Readings'!W605="","",IF('LT Panel Feeder Readings'!W605="",0,'LT Panel Feeder Readings'!W605)+IF('LT Panel Feeder Readings'!Z605="",0,'LT Panel Feeder Readings'!Z605)),"") | D604: =IFERROR(IF('LT Panel Feeder Readings'!BG605="","",IF('LT Panel Feeder Readings'!BG605="",0,'LT Panel Feeder Readings'!BG605)+IF('LT Panel Feeder Readings'!BJ605="",0,'LT Panel Feeder Readings'!BJ605)),"") | E604: =IF(B604="","",B604+IF(C604="",0,C604)+IF(D604="",0,D604)) | F604: =IFERROR(IF('Fuel Status'!E606="","",IF('Fuel Status'!E606="",0,'Fuel Status'!E606)+IF('Fuel Status'!J606="",0,'Fuel Status'!J606)+IF('Fuel Status'!O606="",0,'Fuel Status'!O606)),"") -> 0 | G604: =IF(B604="","",IF(MONTH(A604)<>MONTH(A603),B604,G603+B604)) | H604: =IF(C604="","",IF(MONTH(A604)<>MONTH(A603),C604,H603+C604)) | I604: =IF(D604="","",IF(MONTH(A604)<>MONTH(A603),D604,I603+D604)) | J604: =IF(E604="","",IF(MONTH(A604)<>MONTH(A603),E604,J603+E604)) | N604: =E604*M604/K604 -> #VALUE! | O604: =IF(OR(J604="",L604="",L604=0),"",ROUND(J604/L604,4)) | P604: =IFERROR(IF('Raw Water'!U605="","",'Raw Water'!U605),"") | Q604: =IFERROR(IF(STP!U605="","",STP!U605),"") | R604: =IFERROR(IF(STP!V605="","",STP!V605),"") | S604: =IF(P604="","",P604)
A605: 46625 | B605: =IFERROR(IF('LT Panel Feeder Readings'!E606="","",'LT Panel Feeder Readings'!E606),"") | C605: =IFERROR(IF('LT Panel Feeder Readings'!W606="","",IF('LT Panel Feeder Readings'!W606="",0,'LT Panel Feeder Readings'!W606)+IF('LT Panel Feeder Readings'!Z606="",0,'LT Panel Feeder Readings'!Z606)),"") | D605: =IFERROR(IF('LT Panel Feeder Readings'!BG606="","",IF('LT Panel Feeder Readings'!BG606="",0,'LT Panel Feeder Readings'!BG606)+IF('LT Panel Feeder Readings'!BJ606="",0,'LT Panel Feeder Readings'!BJ606)),"") | E605: =IF(B605="","",B605+IF(C605="",0,C605)+IF(D605="",0,D605)) | F605: =IFERROR(IF('Fuel Status'!E607="","",IF('Fuel Status'!E607="",0,'Fuel Status'!E607)+IF('Fuel Status'!J607="",0,'Fuel Status'!J607)+IF('Fuel Status'!O607="",0,'Fuel Status'!O607)),"") -> 0 | G605: =IF(B605="","",IF(MONTH(A605)<>MONTH(A604),B605,G604+B605)) | H605: =IF(C605="","",IF(MONTH(A605)<>MONTH(A604),C605,H604+C605)) | I605: =IF(D605="","",IF(MONTH(A605)<>MONTH(A604),D605,I604+D605)) | J605: =IF(E605="","",IF(MONTH(A605)<>MONTH(A604),E605,J604+E605)) | N605: =E605*M605/K605 -> #VALUE! | O605: =IF(OR(J605="",L605="",L605=0),"",ROUND(J605/L605,4)) | P605: =IFERROR(IF('Raw Water'!U606="","",'Raw Water'!U606),"") | Q605: =IFERROR(IF(STP!U606="","",STP!U606),"") | R605: =IFERROR(IF(STP!V606="","",STP!V606),"") | S605: =IF(P605="","",P605)
A606: 46626 | B606: =IFERROR(IF('LT Panel Feeder Readings'!E607="","",'LT Panel Feeder Readings'!E607),"") | C606: =IFERROR(IF('LT Panel Feeder Readings'!W607="","",IF('LT Panel Feeder Readings'!W607="",0,'LT Panel Feeder Readings'!W607)+IF('LT Panel Feeder Readings'!Z607="",0,'LT Panel Feeder Readings'!Z607)),"") | D606: =IFERROR(IF('LT Panel Feeder Readings'!BG607="","",IF('LT Panel Feeder Readings'!BG607="",0,'LT Panel Feeder Readings'!BG607)+IF('LT Panel Feeder Readings'!BJ607="",0,'LT Panel Feeder Readings'!BJ607)),"") | E606: =IF(B606="","",B606+IF(C606="",0,C606)+IF(D606="",0,D606)) | F606: =IFERROR(IF('Fuel Status'!E608="","",IF('Fuel Status'!E608="",0,'Fuel Status'!E608)+IF('Fuel Status'!J608="",0,'Fuel Status'!J608)+IF('Fuel Status'!O608="",0,'Fuel Status'!O608)),"") -> 0 | G606: =IF(B606="","",IF(MONTH(A606)<>MONTH(A605),B606,G605+B606)) | H606: =IF(C606="","",IF(MONTH(A606)<>MONTH(A605),C606,H605+C606)) | I606: =IF(D606="","",IF(MONTH(A606)<>MONTH(A605),D606,I605+D606)) | J606: =IF(E606="","",IF(MONTH(A606)<>MONTH(A605),E606,J605+E606)) | N606: =E606*M606/K606 -> #VALUE! | O606: =IF(OR(J606="",L606="",L606=0),"",ROUND(J606/L606,4)) | P606: =IFERROR(IF('Raw Water'!U607="","",'Raw Water'!U607),"") | Q606: =IFERROR(IF(STP!U607="","",STP!U607),"") | R606: =IFERROR(IF(STP!V607="","",STP!V607),"") | S606: =IF(P606="","",P606)
A607: 46627 | B607: =IFERROR(IF('LT Panel Feeder Readings'!E608="","",'LT Panel Feeder Readings'!E608),"") | C607: =IFERROR(IF('LT Panel Feeder Readings'!W608="","",IF('LT Panel Feeder Readings'!W608="",0,'LT Panel Feeder Readings'!W608)+IF('LT Panel Feeder Readings'!Z608="",0,'LT Panel Feeder Readings'!Z608)),"") | D607: =IFERROR(IF('LT Panel Feeder Readings'!BG608="","",IF('LT Panel Feeder Readings'!BG608="",0,'LT Panel Feeder Readings'!BG608)+IF('LT Panel Feeder Readings'!BJ608="",0,'LT Panel Feeder Readings'!BJ608)),"") | E607: =IF(B607="","",B607+IF(C607="",0,C607)+IF(D607="",0,D607)) | F607: =IFERROR(IF('Fuel Status'!E609="","",IF('Fuel Status'!E609="",0,'Fuel Status'!E609)+IF('Fuel Status'!J609="",0,'Fuel Status'!J609)+IF('Fuel Status'!O609="",0,'Fuel Status'!O609)),"") -> 0 | G607: =IF(B607="","",IF(MONTH(A607)<>MONTH(A606),B607,G606+B607)) | H607: =IF(C607="","",IF(MONTH(A607)<>MONTH(A606),C607,H606+C607)) | I607: =IF(D607="","",IF(MONTH(A607)<>MONTH(A606),D607,I606+D607)) | J607: =IF(E607="","",IF(MONTH(A607)<>MONTH(A606),E607,J606+E607)) | N607: =E607*M607/K607 -> #VALUE! | O607: =IF(OR(J607="",L607="",L607=0),"",ROUND(J607/L607,4)) | P607: =IFERROR(IF('Raw Water'!U608="","",'Raw Water'!U608),"") | Q607: =IFERROR(IF(STP!U608="","",STP!U608),"") | R607: =IFERROR(IF(STP!V608="","",STP!V608),"") | S607: =IF(P607="","",P607)
A608: 46628 | B608: =IFERROR(IF('LT Panel Feeder Readings'!E609="","",'LT Panel Feeder Readings'!E609),"") | C608: =IFERROR(IF('LT Panel Feeder Readings'!W609="","",IF('LT Panel Feeder Readings'!W609="",0,'LT Panel Feeder Readings'!W609)+IF('LT Panel Feeder Readings'!Z609="",0,'LT Panel Feeder Readings'!Z609)),"") | D608: =IFERROR(IF('LT Panel Feeder Readings'!BG609="","",IF('LT Panel Feeder Readings'!BG609="",0,'LT Panel Feeder Readings'!BG609)+IF('LT Panel Feeder Readings'!BJ609="",0,'LT Panel Feeder Readings'!BJ609)),"") | E608: =IF(B608="","",B608+IF(C608="",0,C608)+IF(D608="",0,D608)) | F608: =IFERROR(IF('Fuel Status'!E610="","",IF('Fuel Status'!E610="",0,'Fuel Status'!E610)+IF('Fuel Status'!J610="",0,'Fuel Status'!J610)+IF('Fuel Status'!O610="",0,'Fuel Status'!O610)),"") -> 0 | G608: =IF(B608="","",IF(MONTH(A608)<>MONTH(A607),B608,G607+B608)) | H608: =IF(C608="","",IF(MONTH(A608)<>MONTH(A607),C608,H607+C608)) | I608: =IF(D608="","",IF(MONTH(A608)<>MONTH(A607),D608,I607+D608)) | J608: =IF(E608="","",IF(MONTH(A608)<>MONTH(A607),E608,J607+E608)) | N608: =E608*M608/K608 -> #VALUE! | O608: =IF(OR(J608="",L608="",L608=0),"",ROUND(J608/L608,4)) | P608: =IFERROR(IF('Raw Water'!U609="","",'Raw Water'!U609),"") | Q608: =IFERROR(IF(STP!U609="","",STP!U609),"") | R608: =IFERROR(IF(STP!V609="","",STP!V609),"") | S608: =IF(P608="","",P608)
A609: 46629 | B609: =IFERROR(IF('LT Panel Feeder Readings'!E610="","",'LT Panel Feeder Readings'!E610),"") | C609: =IFERROR(IF('LT Panel Feeder Readings'!W610="","",IF('LT Panel Feeder Readings'!W610="",0,'LT Panel Feeder Readings'!W610)+IF('LT Panel Feeder Readings'!Z610="",0,'LT Panel Feeder Readings'!Z610)),"") | D609: =IFERROR(IF('LT Panel Feeder Readings'!BG610="","",IF('LT Panel Feeder Readings'!BG610="",0,'LT Panel Feeder Readings'!BG610)+IF('LT Panel Feeder Readings'!BJ610="",0,'LT Panel Feeder Readings'!BJ610)),"") | E609: =IF(B609="","",B609+IF(C609="",0,C609)+IF(D609="",0,D609)) | F609: =IFERROR(IF('Fuel Status'!E611="","",IF('Fuel Status'!E611="",0,'Fuel Status'!E611)+IF('Fuel Status'!J611="",0,'Fuel Status'!J611)+IF('Fuel Status'!O611="",0,'Fuel Status'!O611)),"") -> 0 | G609: =IF(B609="","",IF(MONTH(A609)<>MONTH(A608),B609,G608+B609)) | H609: =IF(C609="","",IF(MONTH(A609)<>MONTH(A608),C609,H608+C609)) | I609: =IF(D609="","",IF(MONTH(A609)<>MONTH(A608),D609,I608+D609)) | J609: =IF(E609="","",IF(MONTH(A609)<>MONTH(A608),E609,J608+E609)) | N609: =E609*M609/K609 -> #VALUE! | O609: =IF(OR(J609="",L609="",L609=0),"",ROUND(J609/L609,4)) | P609: =IFERROR(IF('Raw Water'!U610="","",'Raw Water'!U610),"") | Q609: =IFERROR(IF(STP!U610="","",STP!U610),"") | R609: =IFERROR(IF(STP!V610="","",STP!V610),"") | S609: =IF(P609="","",P609)
A610: 46630 | B610: =IFERROR(IF('LT Panel Feeder Readings'!E611="","",'LT Panel Feeder Readings'!E611),"") | C610: =IFERROR(IF('LT Panel Feeder Readings'!W611="","",IF('LT Panel Feeder Readings'!W611="",0,'LT Panel Feeder Readings'!W611)+IF('LT Panel Feeder Readings'!Z611="",0,'LT Panel Feeder Readings'!Z611)),"") | D610: =IFERROR(IF('LT Panel Feeder Readings'!BG611="","",IF('LT Panel Feeder Readings'!BG611="",0,'LT Panel Feeder Readings'!BG611)+IF('LT Panel Feeder Readings'!BJ611="",0,'LT Panel Feeder Readings'!BJ611)),"") | E610: =IF(B610="","",B610+IF(C610="",0,C610)+IF(D610="",0,D610)) | F610: =IFERROR(IF('Fuel Status'!E612="","",IF('Fuel Status'!E612="",0,'Fuel Status'!E612)+IF('Fuel Status'!J612="",0,'Fuel Status'!J612)+IF('Fuel Status'!O612="",0,'Fuel Status'!O612)),"") -> 0 | G610: =IF(B610="","",IF(MONTH(A610)<>MONTH(A609),B610,G609+B610)) | H610: =IF(C610="","",IF(MONTH(A610)<>MONTH(A609),C610,H609+C610)) | I610: =IF(D610="","",IF(MONTH(A610)<>MONTH(A609),D610,I609+D610)) | J610: =IF(E610="","",IF(MONTH(A610)<>MONTH(A609),E610,J609+E610)) | N610: =E610*M610/K610 -> #VALUE! | O610: =IF(OR(J610="",L610="",L610=0),"",ROUND(J610/L610,4)) | P610: =IFERROR(IF('Raw Water'!U611="","",'Raw Water'!U611),"") | Q610: =IFERROR(IF(STP!U611="","",STP!U611),"") | R610: =IFERROR(IF(STP!V611="","",STP!V611),"") | S610: =IF(P610="","",P610)
A611: 46631 | B611: =IFERROR(IF('LT Panel Feeder Readings'!E612="","",'LT Panel Feeder Readings'!E612),"") | C611: =IFERROR(IF('LT Panel Feeder Readings'!W612="","",IF('LT Panel Feeder Readings'!W612="",0,'LT Panel Feeder Readings'!W612)+IF('LT Panel Feeder Readings'!Z612="",0,'LT Panel Feeder Readings'!Z612)),"") | D611: =IFERROR(IF('LT Panel Feeder Readings'!BG612="","",IF('LT Panel Feeder Readings'!BG612="",0,'LT Panel Feeder Readings'!BG612)+IF('LT Panel Feeder Readings'!BJ612="",0,'LT Panel Feeder Readings'!BJ612)),"") | E611: =IF(B611="","",B611+IF(C611="",0,C611)+IF(D611="",0,D611)) | F611: =IFERROR(IF('Fuel Status'!E613="","",IF('Fuel Status'!E613="",0,'Fuel Status'!E613)+IF('Fuel Status'!J613="",0,'Fuel Status'!J613)+IF('Fuel Status'!O613="",0,'Fuel Status'!O613)),"") -> 0 | G611: =IF(B611="","",IF(MONTH(A611)<>MONTH(A610),B611,G610+B611)) | H611: =IF(C611="","",IF(MONTH(A611)<>MONTH(A610),C611,H610+C611)) | I611: =IF(D611="","",IF(MONTH(A611)<>MONTH(A610),D611,I610+D611)) | J611: =IF(E611="","",IF(MONTH(A611)<>MONTH(A610),E611,J610+E611)) | N611: =E611*M611/K611 -> #VALUE! | O611: =IF(OR(J611="",L611="",L611=0),"",ROUND(J611/L611,4)) | P611: =IFERROR(IF('Raw Water'!U612="","",'Raw Water'!U612),"") | Q611: =IFERROR(IF(STP!U612="","",STP!U612),"") | R611: =IFERROR(IF(STP!V612="","",STP!V612),"") | S611: =IF(P611="","",P611)
A612: 46632 | B612: =IFERROR(IF('LT Panel Feeder Readings'!E613="","",'LT Panel Feeder Readings'!E613),"") | C612: =IFERROR(IF('LT Panel Feeder Readings'!W613="","",IF('LT Panel Feeder Readings'!W613="",0,'LT Panel Feeder Readings'!W613)+IF('LT Panel Feeder Readings'!Z613="",0,'LT Panel Feeder Readings'!Z613)),"") | D612: =IFERROR(IF('LT Panel Feeder Readings'!BG613="","",IF('LT Panel Feeder Readings'!BG613="",0,'LT Panel Feeder Readings'!BG613)+IF('LT Panel Feeder Readings'!BJ613="",0,'LT Panel Feeder Readings'!BJ613)),"") | E612: =IF(B612="","",B612+IF(C612="",0,C612)+IF(D612="",0,D612)) | F612: =IFERROR(IF('Fuel Status'!E614="","",IF('Fuel Status'!E614="",0,'Fuel Status'!E614)+IF('Fuel Status'!J614="",0,'Fuel Status'!J614)+IF('Fuel Status'!O614="",0,'Fuel Status'!O614)),"") -> 0 | G612: =IF(B612="","",IF(MONTH(A612)<>MONTH(A611),B612,G611+B612)) | H612: =IF(C612="","",IF(MONTH(A612)<>MONTH(A611),C612,H611+C612)) | I612: =IF(D612="","",IF(MONTH(A612)<>MONTH(A611),D612,I611+D612)) | J612: =IF(E612="","",IF(MONTH(A612)<>MONTH(A611),E612,J611+E612)) | N612: =E612*M612/K612 -> #VALUE! | O612: =IF(OR(J612="",L612="",L612=0),"",ROUND(J612/L612,4)) | P612: =IFERROR(IF('Raw Water'!U613="","",'Raw Water'!U613),"") | Q612: =IFERROR(IF(STP!U613="","",STP!U613),"") | R612: =IFERROR(IF(STP!V613="","",STP!V613),"") | S612: =IF(P612="","",P612)
A613: 46633 | B613: =IFERROR(IF('LT Panel Feeder Readings'!E614="","",'LT Panel Feeder Readings'!E614),"") | C613: =IFERROR(IF('LT Panel Feeder Readings'!W614="","",IF('LT Panel Feeder Readings'!W614="",0,'LT Panel Feeder Readings'!W614)+IF('LT Panel Feeder Readings'!Z614="",0,'LT Panel Feeder Readings'!Z614)),"") | D613: =IFERROR(IF('LT Panel Feeder Readings'!BG614="","",IF('LT Panel Feeder Readings'!BG614="",0,'LT Panel Feeder Readings'!BG614)+IF('LT Panel Feeder Readings'!BJ614="",0,'LT Panel Feeder Readings'!BJ614)),"") | E613: =IF(B613="","",B613+IF(C613="",0,C613)+IF(D613="",0,D613)) | F613: =IFERROR(IF('Fuel Status'!E615="","",IF('Fuel Status'!E615="",0,'Fuel Status'!E615)+IF('Fuel Status'!J615="",0,'Fuel Status'!J615)+IF('Fuel Status'!O615="",0,'Fuel Status'!O615)),"") -> 0 | G613: =IF(B613="","",IF(MONTH(A613)<>MONTH(A612),B613,G612+B613)) | H613: =IF(C613="","",IF(MONTH(A613)<>MONTH(A612),C613,H612+C613)) | I613: =IF(D613="","",IF(MONTH(A613)<>MONTH(A612),D613,I612+D613)) | J613: =IF(E613="","",IF(MONTH(A613)<>MONTH(A612),E613,J612+E613)) | N613: =E613*M613/K613 -> #VALUE! | O613: =IF(OR(J613="",L613="",L613=0),"",ROUND(J613/L613,4)) | P613: =IFERROR(IF('Raw Water'!U614="","",'Raw Water'!U614),"") | Q613: =IFERROR(IF(STP!U614="","",STP!U614),"") | R613: =IFERROR(IF(STP!V614="","",STP!V614),"") | S613: =IF(P613="","",P613)
...

Sheet LT Panel Feeder Readings
A1: LT PANEL FEEDER READINGS — Continuous Log | Enter FINAL READING only (00:00 hrs) | Initial=Auto | Consumption=Auto
A2: Date(DD/MM/YYYY) | B2: Month(Auto) | C2: HT Meter (kWh)[HT INCOMER] | F2: HT Meter (kVAh)[HT INCOMER] | I2: Transformer-1 Panel (kWh)[TRANSFORMERS] | L2: Transformer-1 Panel (kVAh)[TRANSFORMERS] | O2: Transformer-2 Panel (kWh)[TRANSFORMERS] | R2: Transformer-2 Panel (kVAh)[TRANSFORMERS] | U2: DG-1 Incomer Panel (kWh)[DG PANELS] | X2: DG-2 Incomer Panel (kWh)[DG PANELS] | AA2: Chiller Panel-1 (kWh)[HVAC/CHILLER] | AD2: Chiller Panel-2 (kWh)[HVAC/CHILLER] | AG2: Chiller Pump Panel (kWh)[HVAC/CHILLER] | AJ2: Main AHU Panel-2 (kWh)[HVAC/CHILLER] | AM2: UPS Input Panel Feeder (kWh)[UPS PANELS] | AP2: Conveyor Feeder-2 (kWh)[CONVEYOR] | AS2: Main Power Panel (kWh)[POWER/SERVICE] | AV2: Common Service Panel (kWh)[POWER/SERVICE] | AY2: Critical Panel Supply (kWh)[POWER/SERVICE] | BB2: Lighting Panel (kWh)[LIGHTING] | BE2: Solar System Panel-1 (kWh)[SOLAR] | BH2: Solar System Panel-2 (kWh)[SOLAR]
